Workbook

Sheet Sheet1
A1: information_date | B1: account_number | C1: pool2 | D1: pool | E1: attorney_name | F1: current_liability | G1: arrears_amount | H1: MIL | I1: mil_72 | J1: legal_ind | K1: Legal_Category | L1: MIL_BUCK | M1: SMJPLRCV_ind | N1: arms_ind | O1: zero_balance | P1: credit_balance | Q1: settlement_raw | R1: settlement_aggressive | S1: settlement_1 | T1: settlement_2 | U1: settlement_3 | V1: EXPOSURE_I9 | W1: expected_loss_i9 | X1: coverage | Y1: expected_recovery
A2: 46250 | B2: 50442209 | C2: Legal | D2: Small Balances between R100 and R200 | E2: Internal | F2: -48935.05 | G2: 0 | H2: 61 | I2: 0 | J2: late | K2: Litigation | L2: 60-65 | P2: 1 | Q2: 0.49297396 | R2: 0.49297396 | S2: 0.49297396 | T2: 0.64086615 | U2: 9.99 | X2: =W2/V2 -> #DIV/0!
A3: 46250 | B3: 50595358 | C3: Legal | D3: Deceased | E3: Velile Tinto & Associates Inc | F3: 315036.98 | G3: 315031.23 | H3: 133 | I3: 1 | J3: late | K3: Deceased | L3: 72+ | Q3: 0.010908657 | R3: 0.1 | S3: 0.25 | T3: 0.325 | U3: 0.325 | V3: 315031.23 | W3: 315031.23 | X3: =W3/V3 -> 1
A4: 46250 | B4: 50652580 | C4: Legal | D4: Charge_off_process | E4: Kemp and Associates | F4: 430573.01 | G4: 164462.03 | H4: 59 | I4: 0 | J4: late | K4: Deceased | L4: 54-59 | Q4: 0.28561154 | R4: 0.28561154 | S4: 0.28561154 | T4: 0.371295 | U4: 0.371295 | V4: 430504.01 | W4: 122742.66 | X4: =W4/V4 -> 0.28511387
A5: 46250 | B5: 50972879 | C5: Legal | E5: Strauss Daly Inc | F5: 0 | G5: -234888.53 | H5: 37 | I5: 0 | J5: late | K5: Litigation | L5: 36-41 | O5: 1 | X5: =W5/V5 -> #DIV/0!
A6: 46250 | B6: 50988325 | C6: Legal | D6: Charge_off_process | E6: Kemp and Associates | F6: 351037.43 | G6: 351037.43 | H6: 113 | I6: 1 | J6: late | K6: Deceased | L6: 72+ | Q6: 0.01977759 | R6: 0.1 | S6: 0.25 | T6: 0.325 | U6: 9.99 | V6: 351037.43 | W6: 351037.43 | X6: =W6/V6 -> 1
A7: 46250 | B7: 51115910 | C7: Legal | F7: 0 | G7: 0 | H7: 118 | I7: 1 | J7: late | K7: Litigation | L7: 72+ | O7: 1 | X7: =W7/V7 -> #DIV/0!
A8: 46250 | B8: 51416791 | C8: Legal | D8: Charge_off_process | E8: Kemp and Associates | F8: 290347.72 | G8: 290278.72 | H8: 61 | I8: 0 | J8: late | K8: Deceased | L8: 60-65 | Q8: 0.27536527 | R8: 0.27536527 | S8: 0.27536527 | T8: 0.35797485 | U8: 9.99 | V8: 290128.82 | W8: 175615.25 | X8: =W8/V8 -> 0.60530097
A9: 46250 | B9: 51591240 | C9: Legal | D9: Deceased | E9: Internal | F9: 1249617.3 | G9: 580387.84 | H9: 46 | I9: 0 | J9: late | K9: Deceased | L9: 42-47 | Q9: 0.42322386 | R9: 0.42322386 | S9: 0.42322386 | T9: 0.52902983 | U9: 0.52902983 | V9: 1244204.1 | W9: 412184.51 | X9: =W9/V9 -> 0.33128368
A10: 46250 | B10: 52072476 | C10: Legal | E10: Fourie Basson Veldtman | F10: 0 | G10: 0 | H10: 37 | I10: 0 | J10: late | K10: Litigation | L10: 36-41 | O10: 1 | X10: =W10/V10 -> #DIV/0!
A11: 46250 | B11: 52082862 | C11: Legal | E11: Sandenberg Nel Haggard | F11: 0 | G11: -1069060 | H11: 109 | I11: 1 | J11: late | K11: Litigation | L11: 72+ | O11: 1 | Q11: 0.022260488 | R11: 0.1 | S11: 0.25 | T11: 0.3125 | U11: 0.3125 | X11: =W11/V11 -> #DIV/0!
A12: 46250 | B12: 52254302 | C12: Legal | D12: Account in Legal Sales In Execution Proc | E12: Velile Tinto & Associates Inc | F12: 694565.55 | G12: 474731.77 | H12: 71 | I12: 0 | J12: late | K12: Litigation | L12: 65-71 | Q12: 0.28507187 | R12: 0.28507187 | S12: 0.28507187 | T12: 0.28507187 | U12: 0.28507187 | V12: 694286.95 | W12: 566369.46 | X12: =W12/V12 -> 0.81575703
A13: 46250 | B13: 52281989 | C13: Legal | D13: Deceased | E13: Velile Tinto & Associates Inc | F13: 924540.41 | G13: 924471.41 | H13: 107 | I13: 1 | J13: late | K13: Deceased | L13: 72+ | Q13: 0.023613729 | R13: 0.1 | S13: 0.25 | T13: 0.325 | U13: 9.99 | V13: 924471.41 | W13: 924471.41 | X13: =W13/V13 -> 1
A14: 46250 | B14: 52444594 | C14: Legal | D14: Deceased | F14: 296629.8 | G14: 296624.05 | H14: 88 | I14: 1 | J14: late | K14: Deceased | L14: 72+ | Q14: 0.04924842 | R14: 0.1 | S14: 0.25 | T14: 0.325 | U14: 0.325 | V14: 296624.05 | W14: 195277.71 | X14: =W14/V14 -> 0.65833404
A15: 46250 | B15: 52751306 | C15: Legal | D15: Deceased | E15: Velile Tinto & Associates Inc | F15: 330686.96 | G15: 330686.96 | H15: 103 | I15: 1 | J15: late | K15: Deceased | L15: 72+ | Q15: 0.026565168 | R15: 0.1 | S15: 0.25 | T15: 0.325 | U15: 0.325 | V15: 330686.96 | W15: 330686.96 | X15: =W15/V15 -> 1
A16: 46250 | B16: 54228015 | C16: Legal | E16: Strauss Daly Inc | F16: 0 | G16: 0 | H16: 48 | I16: 0 | J16: late | K16: Litigation | L16: 48-53 | O16: 1 | X16: =W16/V16 -> #DIV/0!
A17: 46250 | B17: 54345836 | C17: Legal | D17: Charge_off_process | E17: Kemp and Associates | F17: 172426.84 | G17: 172357.84 | H17: 68 | I17: 0 | J17: late | K17: Deceased | L17: 65-71 | Q17: 0.24374453 | R17: 0.24374453 | S17: 0.25 | T17: 0.325 | U17: 0.325 | V17: 172357.84 | W17: 106698.17 | X17: =W17/V17 -> 0.61905028
A18: 46250 | B18: 54372930 | C18: Legal | D18: Account in Legal Sales In Execution Proc | E18: Johnston and Partners | F18: 281375.14 | G18: 281375.14 | H18: 48 | I18: 0 | J18: late | K18: Litigation | L18: 48-53 | Q18: 0.41584028 | R18: 0.41584028 | S18: 0.41584028 | T18: 0.54059237 | U18: 0.54059237 | V18: 281375.14 | W18: 136499.42 | X18: =W18/V18 -> 0.48511543
A19: 46250 | B19: 54967063 | C19: Legal | D19: Deceased | E19: Vezi & De Beer | F19: 180567.78 | G19: 180562.03 | H19: 82 | I19: 1 | J19: late | K19: Deceased | L19: 72+ | Q19: 0.17959562 | R19: 0.17959562 | S19: 0.25 | T19: 0.3125 | U19: 9.99 | V19: 180562.03 | W19: 180562.03 | X19: =W19/V19 -> 1
A20: 46250 | B20: 54984189 | C20: Legal | D20: Charge_off_process | F20: 98999.79 | G20: 98930.79 | H20: 38 | I20: 0 | J20: late | K20: Deceased | L20: 36-41 | Q20: 0.50811232 | R20: 0.50811232 | S20: 0.50811232 | T20: 0.66054601 | U20: 9.99 | V20: 103902.59 | W20: 14617.562 | X20: =W20/V20 -> 0.14068525
A21: 46250 | B21: 55237522 | C21: Legal | E21: Vezi & De Beer | F21: 0 | G21: -217907.78 | H21: 56 | I21: 0 | J21: late | K21: Litigation | L21: 54-59 | O21: 1 | X21: =W21/V21 -> #DIV/0!
A22: 46250 | B22: 55688028 | C22: Legal | D22: Deceased | E22: Velile Tinto & Associates Inc | F22: 649123.45 | G22: 47360.49 | H22: 40 | I22: 0 | J22: late | K22: Deceased | L22: 36-41 | Q22: 0.46039277 | R22: 0.46039277 | S22: 0.46039277 | T22: 0.55247133 | U22: 0.55247133 | V22: 647388.88 | W22: 187370.76 | X22: =W22/V22 -> 0.28942535
A23: 46250 | B23: 55708118 | C23: Legal | D23: Charge_off_process | E23: Strauss Daly Inc | F23: 562493.96 | G23: 562488.21 | H23: 130 | I23: 1 | J23: late | K23: Deceased | L23: 72+ | Q23: 0.011930793 | R23: 0.1 | S23: 0.25 | T23: 0.3 | U23: 0.3 | V23: 562488.21 | W23: 562488.21 | X23: =W23/V23 -> 1
A24: 46250 | B24: 55812284 | C24: Legal | E24: Tim Du Toit Attorneys | F24: 0 | G24: 0 | H24: 36 | I24: 0 | J24: late | K24: Litigation | L24: 36-41 | O24: 1 | X24: =W24/V24 -> #DIV/0!
A25: 46250 | B25: 55843619 | C25: Legal | D25: Charge_off_process | E25: Poswa Inc | F25: 258624.23 | G25: 258555.23 | H25: 65 | I25: 0 | J25: late | K25: Litigation | L25: 60-65 | Q25: 0.35485408 | R25: 0.35485408 | S25: 0.35485408 | T25: 0.4613103 | U25: 9.99 | V25: 258488.48 | W25: 158494.21 | X25: =W25/V25 -> 0.61315772
A26: 46250 | B26: 56077790 | C26: Legal | F26: 0 | G26: 0 | H26: 58 | I26: 0 | J26: late | K26: Litigation | L26: 54-59 | O26: 1 | X26: =W26/V26 -> #DIV/0!
A27: 46250 | B27: 56109153 | C27: Legal | D27: Account in Legal Defended Matters Proces | E27: Velile Tinto & Associates Inc | F27: 1321769.2 | G27: 1321700.2 | H27: 130 | I27: 1 | J27: late | K27: Defended M | L27: 72+ | Q27: 0.13166991 | R27: 0.13166991 | S27: 0.25 | T27: 0.25 | U27: 9.99 | V27: 1321700.2 | W27: 1321700.2 | X27: =W27/V27 -> 1
A28: 46250 | B28: 56115773 | C28: Legal | D28: Deceased | E28: Velile Tinto & Associates Inc | F28: 185267.78 | G28: 30723.82 | H28: 42 | I28: 0 | J28: late | K28: Deceased | L28: 42-47 | Q28: 0.47973979 | R28: 0.47973979 | S28: 0.47973979 | T28: 0.62366173 | U28: 9.99 | V28: 184908.01 | W28: 32842.068 | X28: =W28/V28 -> 0.17761301
A29: 46250 | B29: 56270256 | C29: Legal | D29: Account in Legal Sales In Execution Proc | E29: Strauss Daly Inc | F29: 318298.04 | G29: 318292.29 | H29: 81 | I29: 1 | J29: late | K29: Deceased | L29: 72+ | Q29: 0.18363399 | R29: 0.18363399 | S29: 0.25 | T29: 0.325 | U29: 0.325 | V29: 318211.83 | W29: 318211.83 | X29: =W29/V29 -> 1
A30: 46250 | B30: 56291024 | C30: Legal | D30: Charge_off_process | E30: Velile Tinto & Associates Inc | F30: 820886.37 | G30: 820817.37 | H30: 46 | I30: 0 | J30: late | K30: Litigation | L30: 42-47 | Q30: 0.44408906 | R30: 0.44408906 | S30: 0.44408906 | T30: 0.57731577 | U30: 0.57731577 | V30: 818919.58 | W30: 251181.79 | X30: =W30/V30 -> 0.30672339
A31: 46250 | B31: 56318313 | C31: Legal | D31: Deceased | E31: Internal | F31: 429180.28 | G31: 312928.49 | H31: 41 | I31: 0 | J31: late | K31: Deceased | L31: 36-41 | Q31: 0.46593456 | R31: 0.46593456 | S31: 0.46593456 | T31: 0.60571493 | U31: 9.99 | V31: 430177.39 | W31: 107798.35 | X31: =W31/V31 -> 0.25059045
A32: 46250 | B32: 56391533 | C32: Legal | D32: Charge_off_process | F32: 244132.13 | G32: 34753.64 | H32: 70 | I32: 0 | J32: late | K32: Deceased | L32: 65-71 | Q32: 0.31974018 | R32: 0.31974018 | S32: 0.31974018 | T32: 0.41566223 | U32: 9.99 | V32: 235301.46 | W32: 51128.001 | X32: =W32/V32 -> 0.21728722
A33: 46250 | B33: 56408797 | C33: Legal | D33: Deceased | E33: Velile Tinto & Associates Inc | F33: 616702.73 | G33: 616702.73 | H33: 89 | I33: 1 | J33: late | K33: Deceased | L33: 72+ | Q33: 0.045911496 | R33: 0.1 | S33: 0.25 | T33: 0.3125 | U33: 9.99 | V33: 616702.73 | W33: 616702.73 | X33: =W33/V33 -> 1
A34: 46250 | B34: 56474757 | C34: Legal | D34: Deceased | E34: Velile Tinto & Associates Inc | F34: 364838.41 | G34: 364838.41 | H34: 121 | I34: 1 | J34: late | K34: Deceased | L34: 72+ | Q34: 0.015598947 | R34: 0.1 | S34: 0.25 | T34: 0.3125 | U34: 9.99 | V34: 364838.41 | W34: 364838.41 | X34: =W34/V34 -> 1
A35: 46250 | B35: 56706372 | C35: Legal | D35: Charge_off_process | E35: Velile Tinto & Associates Inc | F35: 70375.3 | G35: 53037.15 | H35: 101 | I35: 1 | J35: late | K35: Deceased | L35: 72+ | Q35: 0.028172555 | R35: 0.1 | S35: 0.25 | T35: 0.325 | U35: 0.325 | V35: 76804 | W35: 76804 | X35: =W35/V35 -> 1
A36: 46250 | B36: 56756337 | C36: Legal | D36: Small Balances between R100 and R200 | E36: Internal | F36: -1047.66 | G36: -432272.76 | H36: 46 | I36: 0 | J36: late | K36: Litigation | L36: 42-47 | P36: 1 | Q36: 0.45573165 | R36: 0.45573165 | S36: 0.45573165 | T36: 0.59245114 | U36: 9.99 | V36: 0 | W36: 0 | X36: =W36/V36 -> #DIV/0!
A37: 46250 | B37: 56974733 | C37: Legal | F37: 0 | G37: 0 | H37: 72 | I37: 1 | J37: late | K37: Litigation | L37: 72+ | O37: 1 | X37: =W37/V37 -> #DIV/0!
A38: 46250 | B38: 57133910 | C38: Legal | D38: Deceased | E38: Internal | F38: 301223.16 | G38: 301217.41 | H38: 104 | I38: 1 | J38: late | K38: Deceased | L38: 72+ | Q38: 0.1016444 | R38: 0.1016444 | S38: 0.25 | T38: 0.325 | U38: 0.325 | V38: 301217.41 | W38: 209096.55 | X38: =W38/V38 -> 0.69417151
A39: 46250 | B39: 57182261 | C39: Legal | D39: Deceased | E39: Kemp and Associates | F39: 254495.1 | G39: 254489.35 | H39: 77 | I39: 1 | J39: late | K39: Deceased | L39: 72+ | Q39: 0.20528726 | R39: 0.20528726 | S39: 0.25 | T39: 0.275 | U39: 9.99 | V39: 254489.35 | W39: 254489.35 | X39: =W39/V39 -> 1
A40: 46250 | B40: 57461438 | C40: Legal | D40: Charge_off_process | E40: Kemp and Associates | F40: 836252.85 | G40: 374378.54 | H40: 37 | I40: 0 | J40: late | K40: Deceased | L40: 36-41 | Q40: 0.48512777 | R40: 0.48512777 | S40: 0.48512777 | T40: 0.60640971 | U40: 0.60640971 | V40: 837077.65 | W40: 201186.73 | X40: =W40/V40 -> 0.24034416
...

Sheet Sheet2
A1: account_number | B1: CUSTOMER_TYPE_CODE | C1: CUSTOMER_TYPE
A2: 8086054891
A3: 51990811
A4: 8085984643
A5: 8088795007
A6: 8059449502
A7: 8076075772
A8: 8064161793
A9: 8093724833
A10: 8072508246
A11: 8076086242
A12: 8071215692
A13: 8081065544
... A1981: 8069363574
A1982: 8069379557 | B1982: 1 | C1982: Private individuals
A1983: 8093785007 | B1983: 1 | C1983: Private individuals
A1984: 8080548503 | B1984: 1 | C1984: Private individuals
A1985: 8069380726 | B1985: 1 | C1985: Private individuals
A1986: 8086088878 | B1986: 1 | C1986: Private individuals
A1987: 8094062995 | B1987: 1 | C1987: Private individuals
A1988: 8094379190 | B1988: 1 | C1988: Private individuals
A1989: 8094340456 | B1989: 1 | C1989: Private individuals
A1990: 8080684765 | B1990: 1 | C1990: Private individuals
A1991: 8094297508 | B1991: 1 | C1991: Private individuals
A1992: 8094249296 | B1992: 1 | C1992: Private individuals
A1993: 8080388802 | B1993: 1 | C1993: Private individuals
... A17462: 8064259457 | B17462: 84 | C17462: Farmers

Sheet deceased
A1: information_date | B1: account_number | C1: pool2 | D1: pool | E1: attorney_name | F1: current_liability | G1: arrears_amount | H1: MIL | I1: mil_72 | J1: legal_ind | K1: Legal_Category | L1: MIL_BUCK | M1: customer_type | N1: settlement_minimum | O1: settlement_maximum | P1: coverage | Q1: expected_recovery_based_on_minimum_settlement
A2: 46250 | B2: 50595358 | C2: Legal | D2: Deceased | E2: Velile Tinto & Associates Inc | F2: 315036.98 | G2: 315031.23 | H2: 133 | I2: 1 | J2: late | K2: Deceased | L2: 72+ | M2: =VLOOKUP(B2,Sheet2!A:C,3,FALSE) -> Joint and several accounts | N2: 0.1 | O2: 0.25 | P2: 1 | Q2: =F2*N2 -> 31503.698
A3: 46250 | B3: 50988325 | C3: Legal | D3: Charge_off_process | E3: Kemp and Associates | F3: 351037.43 | G3: 351037.43 | H3: 113 | I3: 1 | J3: late | K3: Deceased | L3: 72+ | M3: =VLOOKUP(B3,Sheet2!A:C,3,FALSE) -> Joint and several accounts | N3: 0.1 | O3: 0.25 | P3: 1 | Q3: =F3*N3 -> 35103.743
A4: 46250 | B4: 52281989 | C4: Legal | D4: Deceased | E4: Velile Tinto & Associates Inc | F4: 924540.41 | G4: 924471.41 | H4: 107 | I4: 1 | J4: late | K4: Deceased | L4: 72+ | M4: =VLOOKUP(B4,Sheet2!A:C,3,FALSE) -> Private individuals | N4: 0.1 | O4: 0.25 | P4: 1 | Q4: =F4*N4 -> 92454.041
A5: 46250 | B5: 52751306 | C5: Legal | D5: Deceased | E5: Velile Tinto & Associates Inc | F5: 330686.96 | G5: 330686.96 | H5: 103 | I5: 1 | J5: late | K5: Deceased | L5: 72+ | M5: =VLOOKUP(B5,Sheet2!A:C,3,FALSE) -> Joint and several accounts | N5: 0.1 | O5: 0.25 | P5: 1 | Q5: =F5*N5 -> 33068.696
A6: 46250 | B6: 54967063 | C6: Legal | D6: Deceased | E6: Vezi & De Beer | F6: 180567.78 | G6: 180562.03 | H6: 82 | I6: 1 | J6: late | K6: Deceased | L6: 72+ | M6: =VLOOKUP(B6,Sheet2!A:C,3,FALSE) -> Private individuals | N6: 0.17959562 | O6: 0.25 | P6: 1 | Q6: =F6*N6 -> 32429.183
A7: 46250 | B7: 55708118 | C7: Legal | D7: Charge_off_process | E7: Strauss Daly Inc | F7: 562493.96 | G7: 562488.21 | H7: 130 | I7: 1 | J7: late | K7: Deceased | L7: 72+ | M7: =VLOOKUP(B7,Sheet2!A:C,3,FALSE) -> Joint and several accounts | N7: 0.1 | O7: 0.25 | P7: 1 | Q7: =F7*N7 -> 56249.396
A8: 46250 | B8: 56408797 | C8: Legal | D8: Deceased | E8: Velile Tinto & Associates Inc | F8: 616702.73 | G8: 616702.73 | H8: 89 | I8: 1 | J8: late | K8: Deceased | L8: 72+ | M8: =VLOOKUP(B8,Sheet2!A:C,3,FALSE) -> Private individuals | N8: 0.1 | O8: 0.25 | P8: 1 | Q8: =F8*N8 -> 61670.273
A9: 46250 | B9: 56474757 | C9: Legal | D9: Deceased | E9: Velile Tinto & Associates Inc | F9: 364838.41 | G9: 364838.41 | H9: 121 | I9: 1 | J9: late | K9: Deceased | L9: 72+ | M9: =VLOOKUP(B9,Sheet2!A:C,3,FALSE) -> Private individuals | N9: 0.1 | O9: 0.25 | P9: 1 | Q9: =F9*N9 -> 36483.841
A10: 46250 | B10: 56706372 | C10: Legal | D10: Charge_off_process | E10: Velile Tinto & Associates Inc | F10: 70375.3 | G10: 53037.15 | H10: 101 | I10: 1 | J10: late | K10: Deceased | L10: 72+ | M10: =VLOOKUP(B10,Sheet2!A:C,3,FALSE) -> Joint and several accounts | N10: 0.1 | O10: 0.25 | P10: 1 | Q10: =F10*N10 -> 7037.53
A11: 46250 | B11: 57182261 | C11: Legal | D11: Deceased | E11: Kemp and Associates | F11: 254495.1 | G11: 254489.35 | H11: 77 | I11: 1 | J11: late | K11: Deceased | L11: 72+ | M11: =VLOOKUP(B11,Sheet2!A:C,3,FALSE) -> Joint and several accounts | N11: 0.20528726 | O11: 0.25 | P11: 1 | Q11: =F11*N11 -> 52244.602
A12: 46250 | B12: 58191736 | C12: Legal | D12: Charge_off_process | E12: Strauss Daly Inc | F12: 370761.58 | G12: 370692.58 | H12: 72 | I12: 1 | J12: late | K12: Deceased | L12: 72+ | M12: =VLOOKUP(B12,Sheet2!A:C,3,FALSE) -> Private individuals | N12: 0.10678774 | O12: 0.25 | P12: 1 | Q12: =F12*N12 -> 39592.792
A13: 46250 | B13: 58646237 | C13: Legal | D13: Deceased | E13: Sandenberg Nel Haggard | F13: 179426.3 | G13: 174109.57 | H13: 101 | I13: 1 | J13: late | K13: Deceased | L13: 72+ | M13: =VLOOKUP(B13,Sheet2!A:C,3,FALSE) -> Private individuals | N13: 0.1 | O13: 0.25 | P13: 1 | Q13: =F13*N13 -> 17942.63
... A32: 46250 | B32: 8042144373 | C32: Legal | D32: Deceased | E32: Sandenberg Nel Haggard | F32: 253666.12 | G32: 253660.37 | H32: 105 | I32: 1 | J32: late | K32: Deceased | L32: 72+ | M32: =VLOOKUP(B32,Sheet2!A:C,3,FALSE) -> Private individuals | N32: 0.1 | O32: 0.25 | P32: 1 | Q32: =F32*N32 -> 25366.612
A33: 46250 | B33: 8042827751 | C33: Legal | D33: Deceased | F33: 464788.89 | G33: 464788.89 | H33: 107 | I33: 1 | J33: late | K33: Deceased | L33: 72+ | M33: =VLOOKUP(B33,Sheet2!A:C,3,FALSE) -> Private individuals | N33: 0.1 | O33: 0.25 | P33: 1 | Q33: =F33*N33 -> 46478.889
A34: 46250 | B34: 8043014064 | C34: Legal | D34: Deceased | E34: Vezi & De Beer | F34: 390092.68 | G34: 258852.48 | H34: 77 | I34: 1 | J34: late | K34: Deceased | L34: 72+ | M34: =VLOOKUP(B34,Sheet2!A:C,3,FALSE) -> Joint and several accounts | N34: 0.20399151 | O34: 0.25 | P34: 1 | Q34: =F34*N34 -> 79575.595
A35: 46250 | B35: 8043095064 | C35: Legal | D35: Charge_off_process | E35: Strauss Daly Inc | F35: 458942.48 | G35: 290374.59 | H35: 75 | I35: 1 | J35: late | K35: Deceased | L35: 72+ | M35: =VLOOKUP(B35,Sheet2!A:C,3,FALSE) -> Joint and several accounts | N35: 0.21363411 | O35: 0.25 | P35: 1 | Q35: =F35*N35 -> 98045.77
A36: 46250 | B36: 8044107761 | C36: Legal | D36: Deceased | E36: Sandenberg Nel Haggard | F36: 559613.09 | G36: 559613.09 | H36: 79 | I36: 1 | J36: late | K36: Deceased | L36: 72+ | M36: =VLOOKUP(B36,Sheet2!A:C,3,FALSE) -> Joint and several accounts | N36: 0.19423835 | O36: 0.25 | P36: 1 | Q36: =F36*N36 -> 108698.32
A37: 46250 | B37: 8044259841 | C37: Legal | D37: Deceased | E37: Velile Tinto & Associates Inc | F37: 762279.08 | G37: 762279.08 | H37: 80 | I37: 1 | J37: late | K37: Deceased | L37: 72+ | M37: =VLOOKUP(B37,Sheet2!A:C,3,FALSE) -> Private individuals | N37: 0.18064314 | O37: 0.25 | P37: 1 | Q37: =F37*N37 -> 137700.49
A38: 46250 | B38: 8044443927 | C38: Legal | D38: Charge_off_process | E38: Kemp and Associates | F38: 560906.91 | G38: 560901.16 | H38: 100 | I38: 1 | J38: late | K38: Deceased | L38: 72+ | M38: =VLOOKUP(B38,Sheet2!A:C,3,FALSE) -> Joint and several accounts | N38: 0.1 | O38: 0.25 | P38: 1 | Q38: =F38*N38 -> 56090.691
A39: 46250 | B39: 8044708476 | C39: Legal | D39: Deceased | E39: Vezi & De Beer | F39: 420255.12 | G39: 420186.12 | H39: 120 | I39: 1 | J39: late | K39: Deceased | L39: 72+ | M39: =VLOOKUP(B39,Sheet2!A:C,3,FALSE) -> Private individuals | N39: 0.1 | O39: 0.25 | P39: 1 | Q39: =F39*N39 -> 42025.512
A40: 46250 | B40: 8045126801 | C40: Legal | D40: Deceased | E40: Internal | F40: 390714.36 | G40: 348581.3 | H40: 87 | I40: 1 | J40: late | K40: Deceased | L40: 72+ | M40: =VLOOKUP(B40,Sheet2!A:C,3,FALSE) -> Joint and several accounts | N40: 0.1 | O40: 0.25 | P40: 1 | Q40: =F40*N40 -> 39071.436
A41: 46250 | B41: 8045140322 | C41: Legal | D41: Charge_off_process | E41: Strauss Daly Inc | F41: 208395.82 | G41: 208390.07 | H41: 74 | I41: 1 | J41: late | K41: Deceased | L41: 72+ | M41: =VLOOKUP(B41,Sheet2!A:C,3,FALSE) -> Joint and several accounts | N41: 0.21131254 | O41: 0.25 | P41: 1 | Q41: =F41*N41 -> 44036.65
A42: 46250 | B42: 8045154361 | C42: Legal | D42: Deceased | E42: Kemp and Associates | F42: 389260.18 | G42: 389260.18 | H42: 78 | I42: 1 | J42: late | K42: Deceased | L42: 72+ | M42: =VLOOKUP(B42,Sheet2!A:C,3,FALSE) -> Joint and several accounts | N42: 0.19985631 | O42: 0.25 | P42: 1 | Q42: =F42*N42 -> 77796.103
A43: 46250 | B43: 8045218307 | C43: Legal | D43: Charge_off_process | E43: Glover | F43: 938156.9 | G43: 673115.66 | H43: 105 | I43: 1 | J43: late | K43: Deceased | L43: 72+ | M43: =VLOOKUP(B43,Sheet2!A:C,3,FALSE) -> Joint and several accounts | N43: 0.1 | O43: 0.25 | P43: 1 | Q43: =F43*N43 -> 93815.69
A44: 46250 | B44: 8045386099 | C44: Legal | D44: Deceased | E44: Vezi & De Beer | F44: 421007.17 | G44: 309815.48 | H44: 77 | I44: 1 | J44: late | K44: Deceased | L44: 72+ | M44: =VLOOKUP(B44,Sheet2!A:C,3,FALSE) -> Private individuals | N44: 0.20004385 | O44: 0.25 | P44: 1 | Q44: =F44*N44 -> 84219.896
A45: 46250 | B45: 8046429343 | C45: Legal | D45: Deceased | E45: Velile Tinto & Associates Inc | F45: 190896.7 | G45: 190890.95 | H45: 115 | I45: 1 | J45: late | K45: Deceased | L45: 72+ | M45: =VLOOKUP(B45,Sheet2!A:C,3,FALSE) -> Joint and several accounts | N45: 0.1 | O45: 0.25 | P45: 1 | Q45: =F45*N45 -> 19089.67
... A149: 46250 | B149: 8064677093 | C149: Legal | D149: Deceased | E149: Vezi & De Beer | F149: 2048674.9 | G149: 2048605.9 | H149: 110 | I149: 1 | J149: late | K149: Deceased | L149: 72+ | M149: =VLOOKUP(B149,Sheet2!A:C,3,FALSE) -> Joint and several accounts | N149: 0.1 | O149: 0.25 | P149: 1 | Q149: =F149*N149 -> 204867.49
A150: 46250 | B150: 8064741723 | C150: Legal | D150: Deceased | F150: 1733339.6 | G150: 1733270.6 | H150: 119 | I150: 1 | J150: late | K150: Deceased | L150: 72+ | M150: =VLOOKUP(B150,Sheet2!A:C,3,FALSE) -> Private individuals | N150: 0.1 | O150: 0.25 | P150: 1 | Q150: =F150*N150 -> 173333.96
A151: 46250 | B151: 8064774827 | C151: Legal | D151: Charge_off_process | E151: Vezi & De Beer | F151: 285606.97 | G151: 285606.97 | H151: 121 | I151: 1 | J151: late | K151: Deceased | L151: 72+ | M151: =VLOOKUP(B151,Sheet2!A:C,3,FALSE) -> Joint and several accounts | N151: 0.1 | O151: 0.25 | P151: 1 | Q151: =F151*N151 -> 28560.697
A152: 46250 | B152: 8064854857 | C152: Legal | D152: Deceased | E152: Velile Tinto & Associates Inc | F152: 186101.2 | G152: 186095.45 | H152: 130 | I152: 1 | J152: late | K152: Deceased | L152: 72+ | M152: =VLOOKUP(B152,Sheet2!A:C,3,FALSE) -> Private individuals | N152: 0.1 | O152: 0.25 | P152: 1 | Q152: =F152*N152 -> 18610.12
A153: 46250 | B153: 8064932550 | C153: Legal | D153: Deceased | E153: Velile Tinto & Associates Inc | F153: 2900758.1 | G153: 2900689.1 | H153: 99 | I153: 1 | J153: late | K153: Deceased | L153: 72+ | M153: =VLOOKUP(B153,Sheet2!A:C,3,FALSE) -> Joint and several accounts | N153: 0.1 | O153: 0.25 | P153: 1 | Q153: =F153*N153 -> 290075.81
A154: 46250 | B154: 8064974342 | C154: Legal | D154: Deceased | E154: Velile Tinto & Associates Inc | F154: 886664.76 | G154: 886659.01 | H154: 126 | I154: 1 | J154: late | K154: Deceased | L154: 72+ | M154: =VLOOKUP(B154,Sheet2!A:C,3,FALSE) -> Joint and several accounts | N154: 0.1 | O154: 0.25 | P154: 1 | Q154: =F154*N154 -> 88666.476
A155: 46250 | B155: 8065090907 | C155: Legal | D155: Deceased | E155: Velile Tinto & Associates Inc | F155: 1847757.8 | G155: 1847688.8 | H155: 122 | I155: 1 | J155: late | K155: Deceased | L155: 72+ | M155: =VLOOKUP(B155,Sheet2!A:C,3,FALSE) -> Joint and several accounts | N155: 0.1 | O155: 0.25 | P155: 1 | Q155: =F155*N155 -> 184775.78
A156: 46250 | B156: 8065108625 | C156: Legal | D156: Charge_off_process | E156: Kemp and Associates | F156: 293956.18 | G156: 247437.96 | H156: 91 | I156: 1 | J156: late | K156: Deceased | L156: 72+ | M156: =VLOOKUP(B156,Sheet2!A:C,3,FALSE) -> Private individuals | N156: 0.1 | O156: 0.25 | P156: 1 | Q156: =F156*N156 -> 29395.618
A157: 46250 | B157: 8065277737 | C157: Legal | D157: Deceased | E157: Velile Tinto & Associates Inc | F157: 629991.63 | G157: 629985.88 | H157: 101 | I157: 1 | J157: late | K157: Deceased | L157: 72+ | M157: =VLOOKUP(B157,Sheet2!A:C,3,FALSE) -> Joint and several accounts | N157: 0.1 | O157: 0.25 | P157: 1 | Q157: =F157*N157 -> 62999.163
A158: 46250 | B158: 8065293690 | C158: Legal | D158: Charge_off_process | E158: EG Cooper Majiedt Inc | F158: 234414.56 | G158: 234408.81 | H158: 120 | I158: 1 | J158: late | K158: Deceased | L158: 72+ | M158: =VLOOKUP(B158,Sheet2!A:C,3,FALSE) -> Sole Proprietor | N158: 0.1 | O158: 0.25 | P158: 1 | Q158: =F158*N158 -> 23441.456
A159: 46250 | B159: 8065307039 | C159: Legal | D159: Deceased | E159: Kemp and Associates | F159: 820601.88 | G159: 566425.92 | H159: 130 | I159: 1 | J159: late | K159: Deceased | L159: 72+ | M159: =VLOOKUP(B159,Sheet2!A:C,3,FALSE) -> Private individuals | N159: 0.1 | O159: 0.25 | P159: 1 | Q159: =F159*N159 -> 82060.188
A160: 46250 | B160: 8065316109 | C160: Legal | D160: Charge_off_process | E160: Delberg Attorneys | F160: 934625.58 | G160: 934556.58 | H160: 114 | I160: 1 | J160: late | K160: Deceased | L160: 72+ | M160: =VLOOKUP(B160,Sheet2!A:C,3,FALSE) -> Private individuals | N160: 0.1 | O160: 0.25 | P160: 1 | Q160: =F160*N160 -> 93462.558
A161: 46250 | B161: 8065409106 | C161: Legal | D161: Deceased | E161: Sandenberg Nel Haggard | F161: 449576.95 | G161: 449576.95 | H161: 165 | I161: 1 | J161: late | K161: Deceased | L161: 72+ | M161: =VLOOKUP(B161,Sheet2!A:C,3,FALSE) -> Joint and several accounts | N161: 0.1 | O161: 0.25 | P161: 1 | Q161: =F161*N161 -> 44957.695
...
